<?xml version="1.0"?>
<robot xmlns:xacro="http://wiki.ros.org/xacro">

<xacro:macro name="castor" params="prefix x_offset_from_base">

  <joint name="${prefix}_castor_truck_joint" type="fixed">
    <parent link="base_link"/>
    <child link="${prefix}_castor_truck"/>
    <origin xyz="${x_offset_from_base} 0 -0.021" rpy="0 0 0" />
  </joint>

  <link name="${prefix}_castor_truck">
    <visual>
      <geometry>
        <box size="0.04 0.08 0.035"/>
      </geometry>
      <material name="light_wood"/>
    </visual>
  </link>

  <joint name="${prefix}_castor_wheel_joint" type="continuous">
    <parent link="${prefix}_castor_truck"/>
    <child link="${prefix}_castor_wheel"/>
    <origin xyz="0 0 -0.035" rpy="0 0 0" />
    <axis xyz="0 1 0" />
  </joint>

  <link name="${prefix}_castor_wheel">
    <visual>
      <geometry>
        <sphere radius="0.015"/>
      </geometry>
      <material name="rubber"/>
    </visual>
  </link>

</xacro:macro>
</robot>
