<?xml version="1.0"?>

<robot name="pluto">

  <!-- Materials -->
  <material name="wood">
    <color rgba="1 0.973 0.863 1"/>
  </material>
  <material name="rubber">
    <color rgba="0 0 0 1"/>
  </material>

  <!-- Base -->
  <link name="base_link">
    <visual>
      <geometry>
        <cylinder length="0.012" radius="0.25"/>
      </geometry>
      <material name="wood"/>
    </visual>
    <collision>
      <geometry>
        <cylinder length="0.012" radius="0.25"/>
      </geometry>
    </collision>
  </link>

  <!-- Wheels -->
  <joint name="base_to_left_wheel" type="continuous">
    <parent link="base_link"/>
    <child link="left_wheel"/>
    <origin xyz="0 0.188 -0.04" rpy="1.57 0 0" />
    <axis xyz="0 0 1" />
  </joint>

  <joint name="base_to_right_wheel" type="continuous">
    <parent link="base_link"/>
    <child link="right_wheel"/>
    <origin xyz="0 -0.188 -0.04" rpy="1.57 0 0" />
    <axis xyz="0 0 1" />
  </joint>

  <link name="left_wheel">
    <visual>
      <geometry>
        <cylinder length="0.024" radius="0.04"/>
      </geometry>
      <material name="rubber"/>
    </visual>
  </link>

  <link name="right_wheel">
    <visual>
      <geometry>
        <cylinder length="0.024" radius="0.04"/>
      </geometry>
      <material name="rubber"/>
    </visual>
  </link>

  <joint name="left_wheel_truck_a_joint" type="fixed">
    <parent link="base_link"/>
    <child link="left_wheel_truck_a"/>
    <origin xyz="0 0.209 -0.035" rpy="0 0 0" />
    <axis xyz="0 0 1" />
  </joint>

  <joint name="left_wheel_truck_b_joint" type="fixed">
    <parent link="base_link"/>
    <child link="left_wheel_truck_b"/>
    <origin xyz="0 0.167 -0.035" rpy="0 0 0" />
    <axis xyz="0 0 1" />
  </joint>

  <link name="left_wheel_truck_a">
    <visual>
      <geometry>
        <box size="0.16 0.012 0.06"/>
      </geometry>
      <material name="wood"/>
    </visual>
  </link>

  <link name="left_wheel_truck_b">
    <visual>
      <geometry>
        <box size="0.055 0.012 0.06"/>
      </geometry>
      <material name="wood"/>
    </visual>
  </link>

  <!-- Castors -->
  <joint name="back_castor_truck_joint" type="fixed">
    <parent link="base_link"/>
    <child link="back_castor_truck"/>
    <origin xyz="-0.20 0 -0.021" rpy="0 0 0" />
  </joint>

  <link name="back_castor_truck">
    <visual>
      <geometry>
        <box size="0.04 0.08 0.035"/>
      </geometry>
      <material name="wood"/>
    </visual>
  </link>

  <joint name="back_castor_wheel_joint" type="continuous">
    <parent link="back_castor_truck"/>
    <child link="back_castor_wheel"/>
    <origin xyz="0 0 -0.035" rpy="0 0 0" />
    <axis xyz="0 1 0" />
  </joint>

  <link name="back_castor_wheel">
    <visual>
      <geometry>
        <sphere radius="0.015"/>
      </geometry>
      <material name="rubber"/>
    </visual>
  </link>

</robot>

